<?xml version="1.0" ?>
<!-- =================================================================================== -->
<!-- |    This document was autogenerated by xacro from /home/miron/arammis_ws/install/apcar_ros_description/share/apcar_ros_description/urdf/apcar.xacro | -->
<!-- |    EDITING THIS FILE BY HAND IS NOT RECOMMENDED                                 | -->
<!-- =================================================================================== -->
<!-- To work with Gazebo, each link must have an inertial element, even if
the link only serves to connect two joints. To be visible in Gazebo, a link
must have a collision element. Furthermore, the link must have a Gazebo
material. -->
<robot name="apcar">
  <!-- Configurable vehicle settings - modify them according to your vehicle geometry -->
  <!--
		Driving (wheel rotation):
		* effort limit [Nm] - Max motor effort at the wheels, per wheel
			= limit_reserve_multiplier * motor_output_stall_torque / 2
		* velocity limit [rad/s] - Rotational velocity limit for the wheels
			= limit_reserve_multiplier * vehicle_max_speed / wheel_tire_radius
		* damping [Nms/rad] -
		* friction [Nm] -
	-->
  <!-- Configurable vehicle settings - modify them according to your vehicle geometry -->
  <!--
		Driving (wheel rotation):
		* effort limit [Nm] - Max motor effort at the wheels, per wheel
			= limit_reserve_multiplier * motor_output_stall_torque / 2
		* velocity limit [rad/s] - Rotational velocity limit for the wheels
			= limit_reserve_multiplier * vehicle_max_speed / wheel_tire_radius
		* damping [Nms/rad] -
		* friction [Nm] -
	-->
  <material name="black">
    <color rgba="0.0 0.0 0.0 1.0"/>
  </material>
  <material name="grey">
    <color rgba="0.2 0.2 0.2 1.0"/>
  </material>
  <material name="white">
    <color rgba="1.0 1.0 1.0 1.0"/>
  </material>
  <material name="red">
    <color rgba="0.8 0.0 0.0 1.0"/>
  </material>
  <material name="green">
    <color rgba="0.0 0.8 0.0 1.0"/>
  </material>
  <material name="blue">
    <color rgba="0.0 0.0 0.8 1.0"/>
  </material>
  <material name="orange">
    <color rgba="1.0 0.43 0.04 1.0"/>
  </material>
  <material name="brown">
    <color rgba="0.87 0.81 0.76 1.0"/>
  </material>
  <!-- Base link -->
  <link name="base_link">
    <!-- base_link must have geometry so that its axes can be displayed in rviz. -->
    <visual>
      <geometry>
        <box size="0.01 0.01 0.01"/>
      </geometry>
      <material name="black"/>
    </visual>
    <inertial>
      <mass value="10"/>
      <inertia ixx="0.1" ixy="0" ixz="0" iyy="0.1" iyz="0" izz="0.1"/>
    </inertial>
    <gazebo reference="base_link">
      <material>Gazebo/Black</material>
    </gazebo>
  </link>
  <!-- <xacro:property name="vehicle_model" value="apcar" /> -->
  <link name="chassis">
    <visual>
      <origin rpy="1.5707963267948966 0 -3.141592653589793" xyz="0 0 0"/>
      <geometry>
        <mesh filename="package://apcar_ros_description/models/apcar_base.stl"/>
        <!-- <mesh filename="package://apcar_ros_description/models/apcar_simplified.stl" /> -->
      </geometry>
    </visual>
    <collision>
      <origin rpy="1.5707963267948966 0 -3.141592653589793" xyz="0 0 0"/>
      <geometry>
        <mesh filename="package://apcar_ros_description/models/apcar_simplified.stl"/>
      </geometry>
    </collision>
    <inertial>
      <mass value="650.0"/>
      <!-- <origin xyz="0 1.2 0.3" rpy="${radians(90)} 0 ${radians(-90)}" /> -->
      <origin rpy="1.5707963267948966 0 -3.141592653589793" xyz="1.0 0 0.2"/>
      <inertia ixx="600.2" ixy="0.0" ixz="0.0" iyy="227.1" iyz="0.0" izz="591.5"/>
      <!-- <inertia ixx="138.10038264" ixy="0.0" ixz="0.0" iyy="349.35091129" iyz="0.0" izz="254.49745894" /> -->
    </inertial>
  </link>
  <gazebo reference="chassis">
    <selfCollide>True</selfCollide>
    <material>Gazebo/White</material>
  </gazebo>
  <joint name="base_link_to_chassis" type="fixed">
    <parent link="base_link"/>
    <child link="chassis"/>
    <origin rpy="0 0 0" xyz="0 0 0"/>
    <axis xyz="1 0 0"/>
  </joint>
  <gazebo reference="base_link_to_chassis">
    <disableFixedJointLumping>true</disableFixedJointLumping>
  </gazebo>
  <link name="steering_wheel">
    <visual>
      <geometry>
        <mesh filename="package://apcar_ros_description/models/steering_wheel.stl" scale="0.007 0.007 0.007"/>
      </geometry>
    </visual>
    <collision>
      <geometry>
        <cylinder length="0.04" radius="0.18"/>
      </geometry>
    </collision>
    <inertial>
      <mass value="5"/>
      <inertia ixx="0.07656" ixy="0.0" ixz="0.0" iyy="0.08118" iyz="0.0" izz="0.15641"/>
    </inertial>
  </link>
  <joint name="steering_wheel_to_chassis" type="revolute">
    <parent link="chassis"/>
    <child link="steering_wheel"/>
    <origin rpy="1.2217304763960306 0 -1.5707963267948966" xyz="1.7 0.3 0.65"/>
    <axis xyz="0 0 1"/>
    <limit effort="50" lower="-6.283185307179586" upper="6.283185307179586" velocity="6.283185307179586"/>
    <dynamics damping="0.1" friction="0"/>
  </joint>
  <gazebo reference="steering_wheel_to_chassis">
    <provideFeedback>true</provideFeedback>
  </gazebo>
  <!-- ### Links ### -->
  <!-- Wheel -->
  <link name="wheel_front_right">
    <visual>
      <!-- Rotate left wheel 180degrees (lrReflect == -1) -->
      <origin rpy="3.141592653589793 0 0" xyz="0 0 -0.095"/>
      <geometry>
        <mesh filename="package://apcar_ros_description/models/apcar_wheel.stl" scale="1 1 1"/>
      </geometry>
    </visual>
    <collision name="collision_wheel_front_right">
      <origin rpy="3.141592653589793 0 0" xyz="0 0 -0.095"/>
      <geometry>
        <cylinder length="0.02" radius="0.24988162878124287"/>
      </geometry>
    </collision>
    <collision name="collision_wheel_front_right">
      <origin rpy="3.141592653589793 0 0" xyz="0 0 -0.095"/>
      <geometry>
        <cylinder length="0.03" radius="0.24973358585766042"/>
      </geometry>
    </collision>
    <collision name="collision_wheel_front_right">
      <origin rpy="3.141592653589793 0 0" xyz="0 0 -0.095"/>
      <geometry>
        <cylinder length="0.04" radius="0.2495261782047476"/>
      </geometry>
    </collision>
    <collision name="collision_wheel_front_right">
      <origin rpy="3.141592653589793 0 0" xyz="0 0 -0.095"/>
      <geometry>
        <cylinder length="0.05" radius="0.24925925763107154"/>
      </geometry>
    </collision>
    <collision name="collision_wheel_front_right">
      <origin rpy="3.141592653589793 0 0" xyz="0 0 -0.095"/>
      <geometry>
        <cylinder length="0.060000000000000005" radius="0.2489326326966832"/>
      </geometry>
    </collision>
    <collision name="collision_wheel_front_right">
      <origin rpy="3.141592653589793 0 0" xyz="0 0 -0.095"/>
      <geometry>
        <cylinder length="0.07" radius="0.2485460680215925"/>
      </geometry>
    </collision>
    <collision name="collision_wheel_front_right">
      <origin rpy="3.141592653589793 0 0" xyz="0 0 -0.095"/>
      <geometry>
        <cylinder length="0.08" radius="0.24809928342877133"/>
      </geometry>
    </collision>
    <collision name="collision_wheel_front_right">
      <origin rpy="3.141592653589793 0 0" xyz="0 0 -0.095"/>
      <geometry>
        <cylinder length="0.09" radius="0.24759195291432431"/>
      </geometry>
    </collision>
    <collision name="collision_wheel_front_right">
      <origin rpy="3.141592653589793 0 0" xyz="0 0 -0.095"/>
      <geometry>
        <cylinder length="0.09999999999999999" radius="0.24702370343586785"/>
      </geometry>
    </collision>
    <collision name="collision_wheel_front_right">
      <origin rpy="3.141592653589793 0 0" xyz="0 0 -0.095"/>
      <geometry>
        <cylinder length="0.10999999999999999" radius="0.24639411350841486"/>
      </geometry>
    </collision>
    <collision name="collision_wheel_front_right">
      <origin rpy="3.141592653589793 0 0" xyz="0 0 -0.095"/>
      <geometry>
        <cylinder length="0.11999999999999998" radius="0.24570271159514517"/>
      </geometry>
    </collision>
    <collision name="collision_wheel_front_right">
      <origin rpy="3.141592653589793 0 0" xyz="0 0 -0.095"/>
      <geometry>
        <cylinder length="0.12999999999999998" radius="0.2449489742783178"/>
      </geometry>
    </collision>
    <collision name="collision_wheel_front_right">
      <origin rpy="3.141592653589793 0 0" xyz="0 0 -0.095"/>
      <geometry>
        <cylinder length="0.13999999999999999" radius="0.24413232419320535"/>
      </geometry>
    </collision>
    <collision name="collision_wheel_front_right">
      <origin rpy="3.141592653589793 0 0" xyz="0 0 -0.095"/>
      <geometry>
        <cylinder length="0.15" radius="0.24325212770525995"/>
      </geometry>
    </collision>
    <collision name="collision_wheel_front_right">
      <origin rpy="3.141592653589793 0 0" xyz="0 0 -0.095"/>
      <geometry>
        <cylinder length="0.16" radius="0.24230769230769228"/>
      </geometry>
    </collision>
    <collision name="collision_wheel_front_right">
      <origin rpy="3.141592653589793 0 0" xyz="0 0 -0.095"/>
      <geometry>
        <cylinder length="0.17" radius="0.24129826371320184"/>
      </geometry>
    </collision>
    <collision name="collision_wheel_front_right">
      <origin rpy="3.141592653589793 0 0" xyz="0 0 -0.095"/>
      <geometry>
        <cylinder length="0.18000000000000002" radius="0.2402230226096491"/>
      </geometry>
    </collision>
    <inertial>
      <mass value="14"/>
      <origin rpy="3.141592653589793 0 0" xyz="0 0 -0.095"/>
      <inertia ixx="0.26086666666666664" ixy="0" ixz="0" iyy="0.26086666666666664" iyz="0" izz="0.4375"/>
    </inertial>
  </link>
  <!-- Wheel knuckle -->
  <link name="wheel_knuckle_front_right">
    <inertial>
      <mass value="10"/>
      <inertia ixx="0.1" ixy="0" ixz="0" iyy="0.1" iyz="0" izz="0.1"/>
    </inertial>
  </link>
  <link name="steering_link_front_right">
    <inertial>
      <mass value="10"/>
      <inertia ixx="0.1" ixy="0" ixz="0" iyy="0.1" iyz="0" izz="0.1"/>
    </inertial>
  </link>
  <!-- ### Joints ### -->
  <!-- Shock <-> chassis (suspension) -->
  <joint name="shock_absorber_front_right" type="prismatic">
    <parent link="chassis"/>
    <child link="steering_link_front_right"/>
    <origin rpy="0 0 1.5707963267948966" xyz="      2.3      -0.4650000000000001      0.0     "/>
    <axis xyz="0 0 1"/>
    <limit effort="2000.0" lower="-0.15" upper="0.15" velocity="10.0"/>
    <dynamics damping="2000.0" friction="50.0"/>
  </joint>
  <joint name="steering_joint_front_right" type="revolute">
    <parent link="steering_link_front_right"/>
    <child link="wheel_knuckle_front_right"/>
    <axis xyz="0 0 -1"/>
    <limit effort="500.0" lower="-0.3490658503988659" upper="0.3490658503988659" velocity="0.5235987755982988"/>
  </joint>
  <gazebo reference="steering_joint_front_right">
    <provideFeedback>true</provideFeedback>
  </gazebo>
  <!-- Wheel <-> wheel knuckle (main wheel rotation joint) -->
  <joint name="axle_front_right" type="continuous">
    <!-- The left and right axles have the same axis so that identical rotation
				values cause the wheels to rotate in the same direction. -->
    <parent link="wheel_knuckle_front_right"/>
    <child link="wheel_front_right"/>
    <origin rpy="0 1.5707963267948966 0" xyz="0.02 0 0"/>
    <axis xyz="0 0 1"/>
    <limit effort="375.0" velocity="150.0"/>
    <dynamics damping="0.5" friction="0.5"/>
  </joint>
  <!-- Gazebo settings -->
  <gazebo reference="wheel_front_right">
    <selfCollide>True</selfCollide>
    <material>Gazebo/Black</material>
  </gazebo>
  <gazebo reference="shock_absorber_front_right">
    <provideFeedback>true</provideFeedback>
    <implicitSpringDamper>true</implicitSpringDamper>
    <springStiffness>
      
					12000.0
				
    </springStiffness>
    <springReference>-0.15</springReference>
  </gazebo>
  <gazebo reference="axle_front_right">
    <provideFeedback>true</provideFeedback>
  </gazebo>
  <gazebo reference="steering_joint_front_right">
    <provideFeedback>true</provideFeedback>
  </gazebo>
  <!-- Gazebo plugins -->
  <gazebo>
    <plugin filename="libTireFrictionPlugin.so" name="tire_friction_front_right">
      <link_name>wheel_front_right</link_name>
      <friction_static>1.1550000000000002</friction_static>
      <friction_dynamic>1.1</friction_dynamic>
      <slip_dynamic>0.03</slip_dynamic>
      <slip_static>0.02</slip_static>
      <speed_static>1.0</speed_static>
    </plugin>
  </gazebo>
  <!-- ### Links ### -->
  <!-- Wheel -->
  <link name="wheel_front_left">
    <visual>
      <!-- Rotate left wheel 180degrees (lrReflect == -1) -->
      <origin rpy="0.0 0 0" xyz="0 0 0.095"/>
      <geometry>
        <mesh filename="package://apcar_ros_description/models/apcar_wheel.stl" scale="1 1 1"/>
      </geometry>
    </visual>
    <collision name="collision_wheel_front_left">
      <origin rpy="0.0 0 0" xyz="0 0 0.095"/>
      <geometry>
        <cylinder length="0.02" radius="0.24988162878124287"/>
      </geometry>
    </collision>
    <collision name="collision_wheel_front_left">
      <origin rpy="0.0 0 0" xyz="0 0 0.095"/>
      <geometry>
        <cylinder length="0.03" radius="0.24973358585766042"/>
      </geometry>
    </collision>
    <collision name="collision_wheel_front_left">
      <origin rpy="0.0 0 0" xyz="0 0 0.095"/>
      <geometry>
        <cylinder length="0.04" radius="0.2495261782047476"/>
      </geometry>
    </collision>
    <collision name="collision_wheel_front_left">
      <origin rpy="0.0 0 0" xyz="0 0 0.095"/>
      <geometry>
        <cylinder length="0.05" radius="0.24925925763107154"/>
      </geometry>
    </collision>
    <collision name="collision_wheel_front_left">
      <origin rpy="0.0 0 0" xyz="0 0 0.095"/>
      <geometry>
        <cylinder length="0.060000000000000005" radius="0.2489326326966832"/>
      </geometry>
    </collision>
    <collision name="collision_wheel_front_left">
      <origin rpy="0.0 0 0" xyz="0 0 0.095"/>
      <geometry>
        <cylinder length="0.07" radius="0.2485460680215925"/>
      </geometry>
    </collision>
    <collision name="collision_wheel_front_left">
      <origin rpy="0.0 0 0" xyz="0 0 0.095"/>
      <geometry>
        <cylinder length="0.08" radius="0.24809928342877133"/>
      </geometry>
    </collision>
    <collision name="collision_wheel_front_left">
      <origin rpy="0.0 0 0" xyz="0 0 0.095"/>
      <geometry>
        <cylinder length="0.09" radius="0.24759195291432431"/>
      </geometry>
    </collision>
    <collision name="collision_wheel_front_left">
      <origin rpy="0.0 0 0" xyz="0 0 0.095"/>
      <geometry>
        <cylinder length="0.09999999999999999" radius="0.24702370343586785"/>
      </geometry>
    </collision>
    <collision name="collision_wheel_front_left">
      <origin rpy="0.0 0 0" xyz="0 0 0.095"/>
      <geometry>
        <cylinder length="0.10999999999999999" radius="0.24639411350841486"/>
      </geometry>
    </collision>
    <collision name="collision_wheel_front_left">
      <origin rpy="0.0 0 0" xyz="0 0 0.095"/>
      <geometry>
        <cylinder length="0.11999999999999998" radius="0.24570271159514517"/>
      </geometry>
    </collision>
    <collision name="collision_wheel_front_left">
      <origin rpy="0.0 0 0" xyz="0 0 0.095"/>
      <geometry>
        <cylinder length="0.12999999999999998" radius="0.2449489742783178"/>
      </geometry>
    </collision>
    <collision name="collision_wheel_front_left">
      <origin rpy="0.0 0 0" xyz="0 0 0.095"/>
      <geometry>
        <cylinder length="0.13999999999999999" radius="0.24413232419320535"/>
      </geometry>
    </collision>
    <collision name="collision_wheel_front_left">
      <origin rpy="0.0 0 0" xyz="0 0 0.095"/>
      <geometry>
        <cylinder length="0.15" radius="0.24325212770525995"/>
      </geometry>
    </collision>
    <collision name="collision_wheel_front_left">
      <origin rpy="0.0 0 0" xyz="0 0 0.095"/>
      <geometry>
        <cylinder length="0.16" radius="0.24230769230769228"/>
      </geometry>
    </collision>
    <collision name="collision_wheel_front_left">
      <origin rpy="0.0 0 0" xyz="0 0 0.095"/>
      <geometry>
        <cylinder length="0.17" radius="0.24129826371320184"/>
      </geometry>
    </collision>
    <collision name="collision_wheel_front_left">
      <origin rpy="0.0 0 0" xyz="0 0 0.095"/>
      <geometry>
        <cylinder length="0.18000000000000002" radius="0.2402230226096491"/>
      </geometry>
    </collision>
    <inertial>
      <mass value="14"/>
      <origin rpy="0.0 0 0" xyz="0 0 0.095"/>
      <inertia ixx="0.26086666666666664" ixy="0" ixz="0" iyy="0.26086666666666664" iyz="0" izz="0.4375"/>
    </inertial>
  </link>
  <!-- Wheel knuckle -->
  <link name="wheel_knuckle_front_left">
    <inertial>
      <mass value="10"/>
      <inertia ixx="0.1" ixy="0" ixz="0" iyy="0.1" iyz="0" izz="0.1"/>
    </inertial>
  </link>
  <link name="steering_link_front_left">
    <inertial>
      <mass value="10"/>
      <inertia ixx="0.1" ixy="0" ixz="0" iyy="0.1" iyz="0" izz="0.1"/>
    </inertial>
  </link>
  <!-- ### Joints ### -->
  <!-- Shock <-> chassis (suspension) -->
  <joint name="shock_absorber_front_left" type="prismatic">
    <parent link="chassis"/>
    <child link="steering_link_front_left"/>
    <origin rpy="0 0 1.5707963267948966" xyz="      2.3      0.4650000000000001      0.0     "/>
    <axis xyz="0 0 1"/>
    <limit effort="2000.0" lower="-0.15" upper="0.15" velocity="10.0"/>
    <dynamics damping="2000.0" friction="50.0"/>
  </joint>
  <joint name="steering_joint_front_left" type="revolute">
    <parent link="steering_link_front_left"/>
    <child link="wheel_knuckle_front_left"/>
    <axis xyz="0 0 -1"/>
    <limit effort="500.0" lower="-0.3490658503988659" upper="0.3490658503988659" velocity="0.5235987755982988"/>
  </joint>
  <gazebo reference="steering_joint_front_left">
    <provideFeedback>true</provideFeedback>
  </gazebo>
  <!-- Wheel <-> wheel knuckle (main wheel rotation joint) -->
  <joint name="axle_front_left" type="continuous">
    <!-- The left and right axles have the same axis so that identical rotation
				values cause the wheels to rotate in the same direction. -->
    <parent link="wheel_knuckle_front_left"/>
    <child link="wheel_front_left"/>
    <origin rpy="0 1.5707963267948966 0" xyz="-0.02 0 0"/>
    <axis xyz="0 0 1"/>
    <limit effort="375.0" velocity="150.0"/>
    <dynamics damping="0.5" friction="0.5"/>
  </joint>
  <!-- Gazebo settings -->
  <gazebo reference="wheel_front_left">
    <selfCollide>True</selfCollide>
    <material>Gazebo/Black</material>
  </gazebo>
  <gazebo reference="shock_absorber_front_left">
    <provideFeedback>true</provideFeedback>
    <implicitSpringDamper>true</implicitSpringDamper>
    <springStiffness>
      
					12000.0
				
    </springStiffness>
    <springReference>-0.15</springReference>
  </gazebo>
  <gazebo reference="axle_front_left">
    <provideFeedback>true</provideFeedback>
  </gazebo>
  <gazebo reference="steering_joint_front_left">
    <provideFeedback>true</provideFeedback>
  </gazebo>
  <!-- Gazebo plugins -->
  <gazebo>
    <plugin filename="libTireFrictionPlugin.so" name="tire_friction_front_left">
      <link_name>wheel_front_left</link_name>
      <friction_static>1.1550000000000002</friction_static>
      <friction_dynamic>1.1</friction_dynamic>
      <slip_dynamic>0.03</slip_dynamic>
      <slip_static>0.02</slip_static>
      <speed_static>1.0</speed_static>
    </plugin>
  </gazebo>
  <!-- ### Links ### -->
  <!-- Wheel -->
  <link name="wheel_back_right">
    <visual>
      <!-- Rotate left wheel 180degrees (lrReflect == -1) -->
      <origin rpy="3.141592653589793 0 0" xyz="0 0 -0.095"/>
      <geometry>
        <mesh filename="package://apcar_ros_description/models/apcar_wheel.stl" scale="1 1 1"/>
      </geometry>
    </visual>
    <collision name="collision_wheel_back_right">
      <origin rpy="3.141592653589793 0 0" xyz="0 0 -0.095"/>
      <geometry>
        <cylinder length="0.02" radius="0.24988162878124287"/>
      </geometry>
    </collision>
    <collision name="collision_wheel_back_right">
      <origin rpy="3.141592653589793 0 0" xyz="0 0 -0.095"/>
      <geometry>
        <cylinder length="0.03" radius="0.24973358585766042"/>
      </geometry>
    </collision>
    <collision name="collision_wheel_back_right">
      <origin rpy="3.141592653589793 0 0" xyz="0 0 -0.095"/>
      <geometry>
        <cylinder length="0.04" radius="0.2495261782047476"/>
      </geometry>
    </collision>
    <collision name="collision_wheel_back_right">
      <origin rpy="3.141592653589793 0 0" xyz="0 0 -0.095"/>
      <geometry>
        <cylinder length="0.05" radius="0.24925925763107154"/>
      </geometry>
    </collision>
    <collision name="collision_wheel_back_right">
      <origin rpy="3.141592653589793 0 0" xyz="0 0 -0.095"/>
      <geometry>
        <cylinder length="0.060000000000000005" radius="0.2489326326966832"/>
      </geometry>
    </collision>
    <collision name="collision_wheel_back_right">
      <origin rpy="3.141592653589793 0 0" xyz="0 0 -0.095"/>
      <geometry>
        <cylinder length="0.07" radius="0.2485460680215925"/>
      </geometry>
    </collision>
    <collision name="collision_wheel_back_right">
      <origin rpy="3.141592653589793 0 0" xyz="0 0 -0.095"/>
      <geometry>
        <cylinder length="0.08" radius="0.24809928342877133"/>
      </geometry>
    </collision>
    <collision name="collision_wheel_back_right">
      <origin rpy="3.141592653589793 0 0" xyz="0 0 -0.095"/>
      <geometry>
        <cylinder length="0.09" radius="0.24759195291432431"/>
      </geometry>
    </collision>
    <collision name="collision_wheel_back_right">
      <origin rpy="3.141592653589793 0 0" xyz="0 0 -0.095"/>
      <geometry>
        <cylinder length="0.09999999999999999" radius="0.24702370343586785"/>
      </geometry>
    </collision>
    <collision name="collision_wheel_back_right">
      <origin rpy="3.141592653589793 0 0" xyz="0 0 -0.095"/>
      <geometry>
        <cylinder length="0.10999999999999999" radius="0.24639411350841486"/>
      </geometry>
    </collision>
    <collision name="collision_wheel_back_right">
      <origin rpy="3.141592653589793 0 0" xyz="0 0 -0.095"/>
      <geometry>
        <cylinder length="0.11999999999999998" radius="0.24570271159514517"/>
      </geometry>
    </collision>
    <collision name="collision_wheel_back_right">
      <origin rpy="3.141592653589793 0 0" xyz="0 0 -0.095"/>
      <geometry>
        <cylinder length="0.12999999999999998" radius="0.2449489742783178"/>
      </geometry>
    </collision>
    <collision name="collision_wheel_back_right">
      <origin rpy="3.141592653589793 0 0" xyz="0 0 -0.095"/>
      <geometry>
        <cylinder length="0.13999999999999999" radius="0.24413232419320535"/>
      </geometry>
    </collision>
    <collision name="collision_wheel_back_right">
      <origin rpy="3.141592653589793 0 0" xyz="0 0 -0.095"/>
      <geometry>
        <cylinder length="0.15" radius="0.24325212770525995"/>
      </geometry>
    </collision>
    <collision name="collision_wheel_back_right">
      <origin rpy="3.141592653589793 0 0" xyz="0 0 -0.095"/>
      <geometry>
        <cylinder length="0.16" radius="0.24230769230769228"/>
      </geometry>
    </collision>
    <collision name="collision_wheel_back_right">
      <origin rpy="3.141592653589793 0 0" xyz="0 0 -0.095"/>
      <geometry>
        <cylinder length="0.17" radius="0.24129826371320184"/>
      </geometry>
    </collision>
    <collision name="collision_wheel_back_right">
      <origin rpy="3.141592653589793 0 0" xyz="0 0 -0.095"/>
      <geometry>
        <cylinder length="0.18000000000000002" radius="0.2402230226096491"/>
      </geometry>
    </collision>
    <inertial>
      <mass value="14"/>
      <origin rpy="3.141592653589793 0 0" xyz="0 0 -0.095"/>
      <inertia ixx="0.26086666666666664" ixy="0" ixz="0" iyy="0.26086666666666664" iyz="0" izz="0.4375"/>
    </inertial>
  </link>
  <!-- Wheel knuckle -->
  <link name="wheel_knuckle_back_right">
    <inertial>
      <mass value="10"/>
      <inertia ixx="0.1" ixy="0" ixz="0" iyy="0.1" iyz="0" izz="0.1"/>
    </inertial>
  </link>
  <!-- ### Joints ### -->
  <!-- Shock <-> chassis (suspension) -->
  <joint name="shock_absorber_back_right" type="prismatic">
    <parent link="chassis"/>
    <child link="wheel_knuckle_back_right"/>
    <origin rpy="0 0 1.5707963267948966" xyz="      0.0      -0.4650000000000001      0.0     "/>
    <axis xyz="0 0 1"/>
    <limit effort="2000.0" lower="-0.15" upper="0.15" velocity="10.0"/>
    <dynamics damping="2000.0" friction="50.0"/>
  </joint>
  <!-- Wheel <-> wheel knuckle (main wheel rotation joint) -->
  <joint name="axle_back_right" type="continuous">
    <!-- The left and right axles have the same axis so that identical rotation
				values cause the wheels to rotate in the same direction. -->
    <parent link="wheel_knuckle_back_right"/>
    <child link="wheel_back_right"/>
    <origin rpy="0 1.5707963267948966 0" xyz="0.02 0 0"/>
    <axis xyz="0 0 1"/>
    <limit effort="375.0" velocity="150.0"/>
    <dynamics damping="0.5" friction="0.5"/>
  </joint>
  <!-- Gazebo settings -->
  <gazebo reference="wheel_back_right">
    <selfCollide>True</selfCollide>
    <material>Gazebo/Black</material>
  </gazebo>
  <gazebo reference="shock_absorber_back_right">
    <provideFeedback>true</provideFeedback>
    <implicitSpringDamper>true</implicitSpringDamper>
    <springStiffness>
      
					14000.0
				
    </springStiffness>
    <springReference>-0.15</springReference>
  </gazebo>
  <gazebo reference="axle_back_right">
    <provideFeedback>true</provideFeedback>
  </gazebo>
  <!-- Gazebo plugins -->
  <gazebo>
    <plugin filename="libTireFrictionPlugin.so" name="tire_friction_back_right">
      <link_name>wheel_back_right</link_name>
      <friction_static>1.1550000000000002</friction_static>
      <friction_dynamic>1.1</friction_dynamic>
      <slip_dynamic>0.03</slip_dynamic>
      <slip_static>0.02</slip_static>
      <speed_static>1.0</speed_static>
    </plugin>
  </gazebo>
  <!-- ### Links ### -->
  <!-- Wheel -->
  <link name="wheel_back_left">
    <visual>
      <!-- Rotate left wheel 180degrees (lrReflect == -1) -->
      <origin rpy="0.0 0 0" xyz="0 0 0.095"/>
      <geometry>
        <mesh filename="package://apcar_ros_description/models/apcar_wheel.stl" scale="1 1 1"/>
      </geometry>
    </visual>
    <collision name="collision_wheel_back_left">
      <origin rpy="0.0 0 0" xyz="0 0 0.095"/>
      <geometry>
        <cylinder length="0.02" radius="0.24988162878124287"/>
      </geometry>
    </collision>
    <collision name="collision_wheel_back_left">
      <origin rpy="0.0 0 0" xyz="0 0 0.095"/>
      <geometry>
        <cylinder length="0.03" radius="0.24973358585766042"/>
      </geometry>
    </collision>
    <collision name="collision_wheel_back_left">
      <origin rpy="0.0 0 0" xyz="0 0 0.095"/>
      <geometry>
        <cylinder length="0.04" radius="0.2495261782047476"/>
      </geometry>
    </collision>
    <collision name="collision_wheel_back_left">
      <origin rpy="0.0 0 0" xyz="0 0 0.095"/>
      <geometry>
        <cylinder length="0.05" radius="0.24925925763107154"/>
      </geometry>
    </collision>
    <collision name="collision_wheel_back_left">
      <origin rpy="0.0 0 0" xyz="0 0 0.095"/>
      <geometry>
        <cylinder length="0.060000000000000005" radius="0.2489326326966832"/>
      </geometry>
    </collision>
    <collision name="collision_wheel_back_left">
      <origin rpy="0.0 0 0" xyz="0 0 0.095"/>
      <geometry>
        <cylinder length="0.07" radius="0.2485460680215925"/>
      </geometry>
    </collision>
    <collision name="collision_wheel_back_left">
      <origin rpy="0.0 0 0" xyz="0 0 0.095"/>
      <geometry>
        <cylinder length="0.08" radius="0.24809928342877133"/>
      </geometry>
    </collision>
    <collision name="collision_wheel_back_left">
      <origin rpy="0.0 0 0" xyz="0 0 0.095"/>
      <geometry>
        <cylinder length="0.09" radius="0.24759195291432431"/>
      </geometry>
    </collision>
    <collision name="collision_wheel_back_left">
      <origin rpy="0.0 0 0" xyz="0 0 0.095"/>
      <geometry>
        <cylinder length="0.09999999999999999" radius="0.24702370343586785"/>
      </geometry>
    </collision>
    <collision name="collision_wheel_back_left">
      <origin rpy="0.0 0 0" xyz="0 0 0.095"/>
      <geometry>
        <cylinder length="0.10999999999999999" radius="0.24639411350841486"/>
      </geometry>
    </collision>
    <collision name="collision_wheel_back_left">
      <origin rpy="0.0 0 0" xyz="0 0 0.095"/>
      <geometry>
        <cylinder length="0.11999999999999998" radius="0.24570271159514517"/>
      </geometry>
    </collision>
    <collision name="collision_wheel_back_left">
      <origin rpy="0.0 0 0" xyz="0 0 0.095"/>
      <geometry>
        <cylinder length="0.12999999999999998" radius="0.2449489742783178"/>
      </geometry>
    </collision>
    <collision name="collision_wheel_back_left">
      <origin rpy="0.0 0 0" xyz="0 0 0.095"/>
      <geometry>
        <cylinder length="0.13999999999999999" radius="0.24413232419320535"/>
      </geometry>
    </collision>
    <collision name="collision_wheel_back_left">
      <origin rpy="0.0 0 0" xyz="0 0 0.095"/>
      <geometry>
        <cylinder length="0.15" radius="0.24325212770525995"/>
      </geometry>
    </collision>
    <collision name="collision_wheel_back_left">
      <origin rpy="0.0 0 0" xyz="0 0 0.095"/>
      <geometry>
        <cylinder length="0.16" radius="0.24230769230769228"/>
      </geometry>
    </collision>
    <collision name="collision_wheel_back_left">
      <origin rpy="0.0 0 0" xyz="0 0 0.095"/>
      <geometry>
        <cylinder length="0.17" radius="0.24129826371320184"/>
      </geometry>
    </collision>
    <collision name="collision_wheel_back_left">
      <origin rpy="0.0 0 0" xyz="0 0 0.095"/>
      <geometry>
        <cylinder length="0.18000000000000002" radius="0.2402230226096491"/>
      </geometry>
    </collision>
    <inertial>
      <mass value="14"/>
      <origin rpy="0.0 0 0" xyz="0 0 0.095"/>
      <inertia ixx="0.26086666666666664" ixy="0" ixz="0" iyy="0.26086666666666664" iyz="0" izz="0.4375"/>
    </inertial>
  </link>
  <!-- Wheel knuckle -->
  <link name="wheel_knuckle_back_left">
    <inertial>
      <mass value="10"/>
      <inertia ixx="0.1" ixy="0" ixz="0" iyy="0.1" iyz="0" izz="0.1"/>
    </inertial>
  </link>
  <!-- ### Joints ### -->
  <!-- Shock <-> chassis (suspension) -->
  <joint name="shock_absorber_back_left" type="prismatic">
    <parent link="chassis"/>
    <child link="wheel_knuckle_back_left"/>
    <origin rpy="0 0 1.5707963267948966" xyz="      0.0      0.4650000000000001      0.0     "/>
    <axis xyz="0 0 1"/>
    <limit effort="2000.0" lower="-0.15" upper="0.15" velocity="10.0"/>
    <dynamics damping="2000.0" friction="50.0"/>
  </joint>
  <!-- Wheel <-> wheel knuckle (main wheel rotation joint) -->
  <joint name="axle_back_left" type="continuous">
    <!-- The left and right axles have the same axis so that identical rotation
				values cause the wheels to rotate in the same direction. -->
    <parent link="wheel_knuckle_back_left"/>
    <child link="wheel_back_left"/>
    <origin rpy="0 1.5707963267948966 0" xyz="-0.02 0 0"/>
    <axis xyz="0 0 1"/>
    <limit effort="375.0" velocity="150.0"/>
    <dynamics damping="0.5" friction="0.5"/>
  </joint>
  <!-- Gazebo settings -->
  <gazebo reference="wheel_back_left">
    <selfCollide>True</selfCollide>
    <material>Gazebo/Black</material>
  </gazebo>
  <gazebo reference="shock_absorber_back_left">
    <provideFeedback>true</provideFeedback>
    <implicitSpringDamper>true</implicitSpringDamper>
    <springStiffness>
      
					14000.0
				
    </springStiffness>
    <springReference>-0.15</springReference>
  </gazebo>
  <gazebo reference="axle_back_left">
    <provideFeedback>true</provideFeedback>
  </gazebo>
  <!-- Gazebo plugins -->
  <gazebo>
    <plugin filename="libTireFrictionPlugin.so" name="tire_friction_back_left">
      <link_name>wheel_back_left</link_name>
      <friction_static>1.1550000000000002</friction_static>
      <friction_dynamic>1.1</friction_dynamic>
      <slip_dynamic>0.03</slip_dynamic>
      <slip_static>0.02</slip_static>
      <speed_static>1.0</speed_static>
    </plugin>
  </gazebo>
</robot>
